<?xml version="1.0" encoding="UTF-8"?>
<testng-results retried="3" ignored="0" total="5" passed="1" failed="1" skipped="0">
  <reporter-output>
    <line>
      <![CDATA[Inside method1]]>
    </line>
    <line>
      <![CDATA[Inside method2]]>
    </line>
    <line>
      <![CDATA[Inside method2]]>
    </line>
    <line>
      <![CDATA[Inside method2]]>
    </line>
    <line>
      <![CDATA[Inside method2]]>
    </line>
  </reporter-output>
  <suite started-at="2021-11-16T18:00:35 IST" name="Default suite" finished-at="2021-11-16T18:00:36 IST" duration-ms="304">
    <groups>
    </groups>
    <test started-at="2021-11-16T18:00:35 IST" name="Default test" finished-at="2021-11-16T18:00:36 IST" duration-ms="304">
      <class name="com.maven.org.TestRetry">
        <test-method signature="tester1()[pri:0, instance:com.maven.org.TestRetry@6b19b79]" started-at="2021-11-16T18:00:35 IST" name="tester1" finished-at="2021-11-16T18:00:35 IST" duration-ms="39" status="PASS">
          <reporter-output>
            <line>
              <![CDATA[Inside method1]]>
            </line>
          </reporter-output>
        </test-method> <!-- tester1 -->
        <test-method retried="true" signature="tester2()[pri:0, instance:com.maven.org.TestRetry@6b19b79]" started-at="2021-11-16T18:00:35 IST" name="tester2" finished-at="2021-11-16T18:00:35 IST" duration-ms="32" status="SKIP">
          <exception class="junit.framework.AssertionFailedError">
            <message>
              <![CDATA[expected:<false> but was:<true>]]>
            </message>
            <full-stacktrace>
              <![CDATA[junit.framework.AssertionFailedError: expected:<false> but was:<true>
at junit.framework.Assert.fail(Assert.java:57)
at junit.framework.Assert.failNotEquals(Assert.java:329)
at junit.framework.Assert.assertEquals(Assert.java:78)
at junit.framework.Assert.assertEquals(Assert.java:174)
at junit.framework.Assert.assertEquals(Assert.java:181)
at com.maven.org.TestRetry.tester2(TestRetry.java:16)
at java.base/jdk.internal.reflect.NativeMethodAccessorImpl.invoke0(Native Method)
at java.base/jdk.internal.reflect.NativeMethodAccessorImpl.invoke(NativeMethodAccessorImpl.java:62)
at java.base/jdk.internal.reflect.DelegatingMethodAccessorImpl.invoke(DelegatingMethodAccessorImpl.java:43)
at java.base/java.lang.reflect.Method.invoke(Method.java:564)
at org.testng.internal.MethodInvocationHelper.invokeMethod(MethodInvocationHelper.java:134)
at org.testng.internal.TestInvoker.invokeMethod(TestInvoker.java:597)
at org.testng.internal.TestInvoker.invokeTestMethod(TestInvoker.java:173)
at org.testng.internal.MethodRunner.runInSequence(MethodRunner.java:46)
at org.testng.internal.TestInvoker$MethodInvocationAgent.invoke(TestInvoker.java:816)
at org.testng.internal.TestInvoker.invokeTestMethods(TestInvoker.java:146)
at org.testng.internal.TestMethodWorker.invokeTestMethods(TestMethodWorker.java:146)
at org.testng.internal.TestMethodWorker.run(TestMethodWorker.java:128)
at java.base/java.util.ArrayList.forEach(ArrayList.java:1511)
at org.testng.TestRunner.privateRun(TestRunner.java:766)
at org.testng.TestRunner.run(TestRunner.java:587)
at org.testng.SuiteRunner.runTest(SuiteRunner.java:384)
at org.testng.SuiteRunner.runSequentially(SuiteRunner.java:378)
at org.testng.SuiteRunner.privateRun(SuiteRunner.java:337)
at org.testng.SuiteRunner.run(SuiteRunner.java:286)
at org.testng.SuiteRunnerWorker.runSuite(SuiteRunnerWorker.java:53)
at org.testng.SuiteRunnerWorker.run(SuiteRunnerWorker.java:96)
at org.testng.TestNG.runSuitesSequentially(TestNG.java:1187)
at org.testng.TestNG.runSuitesLocally(TestNG.java:1109)
at org.testng.TestNG.runSuites(TestNG.java:1039)
at org.testng.TestNG.run(TestNG.java:1007)
at org.testng.remote.AbstractRemoteTestNG.run(AbstractRemoteTestNG.java:115)
at org.testng.remote.RemoteTestNG.initAndRun(RemoteTestNG.java:251)
at org.testng.remote.RemoteTestNG.main(RemoteTestNG.java:77)
]]>
            </full-stacktrace>
          </exception> <!-- junit.framework.AssertionFailedError -->
          <reporter-output>
            <line>
              <![CDATA[Inside method2]]>
            </line>
          </reporter-output>
        </test-method> <!-- tester2 -->
        <test-method retried="true" signature="tester2()[pri:0, instance:com.maven.org.TestRetry@6b19b79]" started-at="2021-11-16T18:00:35 IST" name="tester2" finished-at="2021-11-16T18:00:35 IST" duration-ms="3" status="SKIP">
          <exception class="junit.framework.AssertionFailedError">
            <message>
              <![CDATA[expected:<false> but was:<true>]]>
            </message>
            <full-stacktrace>
              <![CDATA[junit.framework.AssertionFailedError: expected:<false> but was:<true>
at junit.framework.Assert.fail(Assert.java:57)
at junit.framework.Assert.failNotEquals(Assert.java:329)
at junit.framework.Assert.assertEquals(Assert.java:78)
at junit.framework.Assert.assertEquals(Assert.java:174)
at junit.framework.Assert.assertEquals(Assert.java:181)
at com.maven.org.TestRetry.tester2(TestRetry.java:16)
at java.base/jdk.internal.reflect.NativeMethodAccessorImpl.invoke0(Native Method)
at java.base/jdk.internal.reflect.NativeMethodAccessorImpl.invoke(NativeMethodAccessorImpl.java:62)
at java.base/jdk.internal.reflect.DelegatingMethodAccessorImpl.invoke(DelegatingMethodAccessorImpl.java:43)
at java.base/java.lang.reflect.Method.invoke(Method.java:564)
at org.testng.internal.MethodInvocationHelper.invokeMethod(MethodInvocationHelper.java:134)
at org.testng.internal.TestInvoker.invokeMethod(TestInvoker.java:597)
at org.testng.internal.TestInvoker.retryFailed(TestInvoker.java:213)
at org.testng.internal.MethodRunner.runInSequence(MethodRunner.java:58)
at org.testng.internal.TestInvoker$MethodInvocationAgent.invoke(TestInvoker.java:816)
at org.testng.internal.TestInvoker.invokeTestMethods(TestInvoker.java:146)
at org.testng.internal.TestMethodWorker.invokeTestMethods(TestMethodWorker.java:146)
at org.testng.internal.TestMethodWorker.run(TestMethodWorker.java:128)
at java.base/java.util.ArrayList.forEach(ArrayList.java:1511)
at org.testng.TestRunner.privateRun(TestRunner.java:766)
at org.testng.TestRunner.run(TestRunner.java:587)
at org.testng.SuiteRunner.runTest(SuiteRunner.java:384)
at org.testng.SuiteRunner.runSequentially(SuiteRunner.java:378)
at org.testng.SuiteRunner.privateRun(SuiteRunner.java:337)
at org.testng.SuiteRunner.run(SuiteRunner.java:286)
at org.testng.SuiteRunnerWorker.runSuite(SuiteRunnerWorker.java:53)
at org.testng.SuiteRunnerWorker.run(SuiteRunnerWorker.java:96)
at org.testng.TestNG.runSuitesSequentially(TestNG.java:1187)
at org.testng.TestNG.runSuitesLocally(TestNG.java:1109)
at org.testng.TestNG.runSuites(TestNG.java:1039)
at org.testng.TestNG.run(TestNG.java:1007)
at org.testng.remote.AbstractRemoteTestNG.run(AbstractRemoteTestNG.java:115)
at org.testng.remote.RemoteTestNG.initAndRun(RemoteTestNG.java:251)
at org.testng.remote.RemoteTestNG.main(RemoteTestNG.java:77)
]]>
            </full-stacktrace>
          </exception> <!-- junit.framework.AssertionFailedError -->
          <reporter-output>
            <line>
              <![CDATA[Inside method2]]>
            </line>
          </reporter-output>
        </test-method> <!-- tester2 -->
        <test-method retried="true" signature="tester2()[pri:0, instance:com.maven.org.TestRetry@6b19b79]" started-at="2021-11-16T18:00:35 IST" name="tester2" finished-at="2021-11-16T18:00:35 IST" duration-ms="10" status="SKIP">
          <exception class="junit.framework.AssertionFailedError">
            <message>
              <![CDATA[expected:<false> but was:<true>]]>
            </message>
            <full-stacktrace>
              <![CDATA[junit.framework.AssertionFailedError: expected:<false> but was:<true>
at junit.framework.Assert.fail(Assert.java:57)
at junit.framework.Assert.failNotEquals(Assert.java:329)
at junit.framework.Assert.assertEquals(Assert.java:78)
at junit.framework.Assert.assertEquals(Assert.java:174)
at junit.framework.Assert.assertEquals(Assert.java:181)
at com.maven.org.TestRetry.tester2(TestRetry.java:16)
at java.base/jdk.internal.reflect.NativeMethodAccessorImpl.invoke0(Native Method)
at java.base/jdk.internal.reflect.NativeMethodAccessorImpl.invoke(NativeMethodAccessorImpl.java:62)
at java.base/jdk.internal.reflect.DelegatingMethodAccessorImpl.invoke(DelegatingMethodAccessorImpl.java:43)
at java.base/java.lang.reflect.Method.invoke(Method.java:564)
at org.testng.internal.MethodInvocationHelper.invokeMethod(MethodInvocationHelper.java:134)
at org.testng.internal.TestInvoker.invokeMethod(TestInvoker.java:597)
at org.testng.internal.TestInvoker.retryFailed(TestInvoker.java:213)
at org.testng.internal.MethodRunner.runInSequence(MethodRunner.java:58)
at org.testng.internal.TestInvoker$MethodInvocationAgent.invoke(TestInvoker.java:816)
at org.testng.internal.TestInvoker.invokeTestMethods(TestInvoker.java:146)
at org.testng.internal.TestMethodWorker.invokeTestMethods(TestMethodWorker.java:146)
at org.testng.internal.TestMethodWorker.run(TestMethodWorker.java:128)
at java.base/java.util.ArrayList.forEach(ArrayList.java:1511)
at org.testng.TestRunner.privateRun(TestRunner.java:766)
at org.testng.TestRunner.run(TestRunner.java:587)
at org.testng.SuiteRunner.runTest(SuiteRunner.java:384)
at org.testng.SuiteRunner.runSequentially(SuiteRunner.java:378)
at org.testng.SuiteRunner.privateRun(SuiteRunner.java:337)
at org.testng.SuiteRunner.run(SuiteRunner.java:286)
at org.testng.SuiteRunnerWorker.runSuite(SuiteRunnerWorker.java:53)
at org.testng.SuiteRunnerWorker.run(SuiteRunnerWorker.java:96)
at org.testng.TestNG.runSuitesSequentially(TestNG.java:1187)
at org.testng.TestNG.runSuitesLocally(TestNG.java:1109)
at org.testng.TestNG.runSuites(TestNG.java:1039)
at org.testng.TestNG.run(TestNG.java:1007)
at org.testng.remote.AbstractRemoteTestNG.run(AbstractRemoteTestNG.java:115)
at org.testng.remote.RemoteTestNG.initAndRun(RemoteTestNG.java:251)
at org.testng.remote.RemoteTestNG.main(RemoteTestNG.java:77)
]]>
            </full-stacktrace>
          </exception> <!-- junit.framework.AssertionFailedError -->
          <reporter-output>
            <line>
              <![CDATA[Inside method2]]>
            </line>
          </reporter-output>
        </test-method> <!-- tester2 -->
        <test-method signature="tester2()[pri:0, instance:com.maven.org.TestRetry@6b19b79]" started-at="2021-11-16T18:00:35 IST" name="tester2" finished-at="2021-11-16T18:00:35 IST" duration-ms="4" status="FAIL">
          <exception class="junit.framework.AssertionFailedError">
            <message>
              <![CDATA[expected:<false> but was:<true>]]>
            </message>
            <full-stacktrace>
              <![CDATA[junit.framework.AssertionFailedError: expected:<false> but was:<true>
at junit.framework.Assert.fail(Assert.java:57)
at junit.framework.Assert.failNotEquals(Assert.java:329)
at junit.framework.Assert.assertEquals(Assert.java:78)
at junit.framework.Assert.assertEquals(Assert.java:174)
at junit.framework.Assert.assertEquals(Assert.java:181)
at com.maven.org.TestRetry.tester2(TestRetry.java:16)
at java.base/jdk.internal.reflect.NativeMethodAccessorImpl.invoke0(Native Method)
at java.base/jdk.internal.reflect.NativeMethodAccessorImpl.invoke(NativeMethodAccessorImpl.java:62)
at java.base/jdk.internal.reflect.DelegatingMethodAccessorImpl.invoke(DelegatingMethodAccessorImpl.java:43)
at java.base/java.lang.reflect.Method.invoke(Method.java:564)
at org.testng.internal.MethodInvocationHelper.invokeMethod(MethodInvocationHelper.java:134)
at org.testng.internal.TestInvoker.invokeMethod(TestInvoker.java:597)
at org.testng.internal.TestInvoker.retryFailed(TestInvoker.java:213)
at org.testng.internal.MethodRunner.runInSequence(MethodRunner.java:58)
at org.testng.internal.TestInvoker$MethodInvocationAgent.invoke(TestInvoker.java:816)
at org.testng.internal.TestInvoker.invokeTestMethods(TestInvoker.java:146)
at org.testng.internal.TestMethodWorker.invokeTestMethods(TestMethodWorker.java:146)
at org.testng.internal.TestMethodWorker.run(TestMethodWorker.java:128)
at java.base/java.util.ArrayList.forEach(ArrayList.java:1511)
at org.testng.TestRunner.privateRun(TestRunner.java:766)
at org.testng.TestRunner.run(TestRunner.java:587)
at org.testng.SuiteRunner.runTest(SuiteRunner.java:384)
at org.testng.SuiteRunner.runSequentially(SuiteRunner.java:378)
at org.testng.SuiteRunner.privateRun(SuiteRunner.java:337)
at org.testng.SuiteRunner.run(SuiteRunner.java:286)
at org.testng.SuiteRunnerWorker.runSuite(SuiteRunnerWorker.java:53)
at org.testng.SuiteRunnerWorker.run(SuiteRunnerWorker.java:96)
at org.testng.TestNG.runSuitesSequentially(TestNG.java:1187)
at org.testng.TestNG.runSuitesLocally(TestNG.java:1109)
at org.testng.TestNG.runSuites(TestNG.java:1039)
at org.testng.TestNG.run(TestNG.java:1007)
at org.testng.remote.AbstractRemoteTestNG.run(AbstractRemoteTestNG.java:115)
at org.testng.remote.RemoteTestNG.initAndRun(RemoteTestNG.java:251)
at org.testng.remote.RemoteTestNG.main(RemoteTestNG.java:77)
]]>
            </full-stacktrace>
          </exception> <!-- junit.framework.AssertionFailedError -->
          <reporter-output>
            <line>
              <![CDATA[Inside method2]]>
            </line>
          </reporter-output>
        </test-method> <!-- tester2 -->
      </class> <!-- com.maven.org.TestRetry -->
    </test> <!-- Default test -->
  </suite> <!-- Default suite -->
</testng-results>
